2022-01-16 11:02:09 - ERROR - getter.py - 35 - An error has been caught in function '<module>', process 'MainProcess' (10260), thread 'MainThread' (14056):
Traceback (most recent call last):

  File "D:\Apps\Python\miniconda3\envs\py37\lib\site-packages\redis\connection.py", line 559, in connect
    sock = self._connect()
           │    └ <function Connection._connect at 0x000001F42B31F048>
           └ Connection<host=localhost,port=6379,db=0>

  File "D:\Apps\Python\miniconda3\envs\py37\lib\site-packages\redis\connection.py", line 615, in _connect
    raise err
          └ ConnectionRefusedError(10061, '由于目标计算机积极拒绝，无法连接。', None, 10061, None)

  File "D:\Apps\Python\miniconda3\envs\py37\lib\site-packages\redis\connection.py", line 603, in _connect
    sock.connect(socket_address)
    │    │       └ ('127.0.0.1', 6379)
    │    └ <method 'connect' of '_socket.socket' objects>
    └ <socket.socket [closed] fd=-1, family=AddressFamily.AF_INET, type=SocketKind.SOCK_STREAM, proto=0>

ConnectionRefusedError: [WinError 10061] 由于目标计算机积极拒绝，无法连接。


During handling of the above exception, another exception occurred:


Traceback (most recent call last):

> File "D:/WorkSpace/pycharm-workspace/ProxyPool/proxypool/components/getter.py", line 35, in <module>
    getter.run()
    │      └ <function Getter.run at 0x000001F42B4393A8>
    └ <__main__.Getter object at 0x000001F428ADA308>

  File "D:/WorkSpace/pycharm-workspace/ProxyPool/proxypool/components/getter.py", line 25, in run
    if self.is_full():
       │    └ <function Getter.is_full at 0x000001F42B439288>
       └ <__main__.Getter object at 0x000001F428ADA308>

  File "D:/WorkSpace/pycharm-workspace/ProxyPool/proxypool/components/getter.py", line 21, in is_full
    return self.redis.count() >= PROXY_NUMBER_MAX
           │    │     │          └ 50000
           │    │     └ <function RedisClient.count at 0x000001F42B430DC8>
           │    └ <proxypool.components.redisclient.RedisClient object at 0x000001F42B42E948>
           └ <__main__.Getter object at 0x000001F428ADA308>

  File "D:\WorkSpace\pycharm-workspace\ProxyPool\proxypool\components\redisclient.py", line 48, in count
    return self.db.zcard(REDIS_KEY)
           │    │  │     └ 'proxy:baidu'
           │    │  └ <function Redis.zcard at 0x000001F42B33DD38>
           │    └ Redis<ConnectionPool<Connection<host=localhost,port=6379,db=0>>>
           └ <proxypool.components.redisclient.RedisClient object at 0x000001F42B42E948>

  File "D:\Apps\Python\miniconda3\envs\py37\lib\site-packages\redis\client.py", line 2692, in zcard
    return self.execute_command('ZCARD', name)
           │    │                        └ 'proxy:baidu'
           │    └ <function Redis.execute_command at 0x000001F42B336D38>
           └ Redis<ConnectionPool<Connection<host=localhost,port=6379,db=0>>>

  File "D:\Apps\Python\miniconda3\envs\py37\lib\site-packages\redis\client.py", line 898, in execute_command
    conn = self.connection or pool.get_connection(command_name, **options)
           │    │             │    │              │               └ {}
           │    │             │    │              └ 'ZCARD'
           │    │             │    └ <function ConnectionPool.get_connection at 0x000001F42B31FD38>
           │    │             └ ConnectionPool<Connection<host=localhost,port=6379,db=0>>
           │    └ None
           └ Redis<ConnectionPool<Connection<host=localhost,port=6379,db=0>>>

  File "D:\Apps\Python\miniconda3\envs\py37\lib\site-packages\redis\connection.py", line 1192, in get_connection
    connection.connect()
    │          └ <function Connection.connect at 0x000001F42B318F78>
    └ Connection<host=localhost,port=6379,db=0>

  File "D:\Apps\Python\miniconda3\envs\py37\lib\site-packages\redis\connection.py", line 563, in connect
    raise ConnectionError(self._error_message(e))
          │               │    └ <function Connection._error_message at 0x000001F42B31F0D8>
          │               └ Connection<host=localhost,port=6379,db=0>
          └ <class 'redis.exceptions.ConnectionError'>

redis.exceptions.ConnectionError: Error 10061 connecting to localhost:6379. 由于目标计算机积极拒绝，无法连接。.
2022-01-16 11:02:09 - ERROR - getter.py - 35 - An error has been caught in function '<module>', process 'MainProcess' (10260), thread 'MainThread' (14056):
Traceback (most recent call last):

  File "D:\Apps\Python\miniconda3\envs\py37\lib\site-packages\redis\connection.py", line 559, in connect
    sock = self._connect()
           │    └ <function Connection._connect at 0x000001F42B31F048>
           └ Connection<host=localhost,port=6379,db=0>

  File "D:\Apps\Python\miniconda3\envs\py37\lib\site-packages\redis\connection.py", line 615, in _connect
    raise err
          └ ConnectionRefusedError(10061, '由于目标计算机积极拒绝，无法连接。', None, 10061, None)

  File "D:\Apps\Python\miniconda3\envs\py37\lib\site-packages\redis\connection.py", line 603, in _connect
    sock.connect(socket_address)
    │    │       └ ('127.0.0.1', 6379)
    │    └ <method 'connect' of '_socket.socket' objects>
    └ <socket.socket [closed] fd=-1, family=AddressFamily.AF_INET, type=SocketKind.SOCK_STREAM, proto=0>

ConnectionRefusedError: [WinError 10061] 由于目标计算机积极拒绝，无法连接。


During handling of the above exception, another exception occurred:


Traceback (most recent call last):

> File "D:/WorkSpace/pycharm-workspace/ProxyPool/proxypool/components/getter.py", line 35, in <module>
    getter.run()
    │      └ <function Getter.run at 0x000001F42B4393A8>
    └ <__main__.Getter object at 0x000001F428ADA308>

  File "D:/WorkSpace/pycharm-workspace/ProxyPool/proxypool/components/getter.py", line 25, in run
    if self.is_full():
       │    └ <function Getter.is_full at 0x000001F42B439288>
       └ <__main__.Getter object at 0x000001F428ADA308>

  File "D:/WorkSpace/pycharm-workspace/ProxyPool/proxypool/components/getter.py", line 21, in is_full
    return self.redis.count() >= PROXY_NUMBER_MAX
           │    │     │          └ 50000
           │    │     └ <function RedisClient.count at 0x000001F42B430DC8>
           │    └ <proxypool.components.redisclient.RedisClient object at 0x000001F42B42E948>
           └ <__main__.Getter object at 0x000001F428ADA308>

  File "D:\WorkSpace\pycharm-workspace\ProxyPool\proxypool\components\redisclient.py", line 48, in count
    return self.db.zcard(REDIS_KEY)
           │    │  │     └ 'proxy:baidu'
           │    │  └ <function Redis.zcard at 0x000001F42B33DD38>
           │    └ Redis<ConnectionPool<Connection<host=localhost,port=6379,db=0>>>
           └ <proxypool.components.redisclient.RedisClient object at 0x000001F42B42E948>

  File "D:\Apps\Python\miniconda3\envs\py37\lib\site-packages\redis\client.py", line 2692, in zcard
    return self.execute_command('ZCARD', name)
           │    │                        └ 'proxy:baidu'
           │    └ <function Redis.execute_command at 0x000001F42B336D38>
           └ Redis<ConnectionPool<Connection<host=localhost,port=6379,db=0>>>

  File "D:\Apps\Python\miniconda3\envs\py37\lib\site-packages\redis\client.py", line 898, in execute_command
    conn = self.connection or pool.get_connection(command_name, **options)
           │    │             │    │              │               └ {}
           │    │             │    │              └ 'ZCARD'
           │    │             │    └ <function ConnectionPool.get_connection at 0x000001F42B31FD38>
           │    │             └ ConnectionPool<Connection<host=localhost,port=6379,db=0>>
           │    └ None
           └ Redis<ConnectionPool<Connection<host=localhost,port=6379,db=0>>>

  File "D:\Apps\Python\miniconda3\envs\py37\lib\site-packages\redis\connection.py", line 1192, in get_connection
    connection.connect()
    │          └ <function Connection.connect at 0x000001F42B318F78>
    └ Connection<host=localhost,port=6379,db=0>

  File "D:\Apps\Python\miniconda3\envs\py37\lib\site-packages\redis\connection.py", line 563, in connect
    raise ConnectionError(self._error_message(e))
          │               │    └ <function Connection._error_message at 0x000001F42B31F0D8>
          │               └ Connection<host=localhost,port=6379,db=0>
          └ <class 'redis.exceptions.ConnectionError'>

redis.exceptions.ConnectionError: Error 10061 connecting to localhost:6379. 由于目标计算机积极拒绝，无法连接。.
2022-01-16 11:07:47 - ERROR - getter.py - 35 - An error has been caught in function '<module>', process 'MainProcess' (620), thread 'MainThread' (13020):
Traceback (most recent call last):

  File "D:\Apps\Python\miniconda3\envs\py37\lib\site-packages\redis\connection.py", line 559, in connect
    sock = self._connect()
           │    └ <function Connection._connect at 0x0000021BE555F048>
           └ Connection<host=localhost,port=6379,db=0>

  File "D:\Apps\Python\miniconda3\envs\py37\lib\site-packages\redis\connection.py", line 615, in _connect
    raise err
          └ ConnectionRefusedError(10061, '由于目标计算机积极拒绝，无法连接。', None, 10061, None)

  File "D:\Apps\Python\miniconda3\envs\py37\lib\site-packages\redis\connection.py", line 603, in _connect
    sock.connect(socket_address)
    │    │       └ ('127.0.0.1', 6379)
    │    └ <method 'connect' of '_socket.socket' objects>
    └ <socket.socket [closed] fd=-1, family=AddressFamily.AF_INET, type=SocketKind.SOCK_STREAM, proto=0>

ConnectionRefusedError: [WinError 10061] 由于目标计算机积极拒绝，无法连接。


During handling of the above exception, another exception occurred:


Traceback (most recent call last):

> File "D:/WorkSpace/pycharm-workspace/ProxyPool/proxypool/components/getter.py", line 35, in <module>
    getter.run()
    │      └ <function Getter.run at 0x0000021BE56783A8>
    └ <__main__.Getter object at 0x0000021BE2D2A348>

  File "D:/WorkSpace/pycharm-workspace/ProxyPool/proxypool/components/getter.py", line 25, in run
    if self.is_full():
       │    └ <function Getter.is_full at 0x0000021BE5678288>
       └ <__main__.Getter object at 0x0000021BE2D2A348>

  File "D:/WorkSpace/pycharm-workspace/ProxyPool/proxypool/components/getter.py", line 21, in is_full
    return self.redis.count() >= PROXY_NUMBER_MAX
           │    │     │          └ 50000
           │    │     └ <function RedisClient.count at 0x0000021BE5670DC8>
           │    └ <proxypool.components.redisclient.RedisClient object at 0x0000021BE566E708>
           └ <__main__.Getter object at 0x0000021BE2D2A348>

  File "D:\WorkSpace\pycharm-workspace\ProxyPool\proxypool\components\redisclient.py", line 48, in count
    return self.db.zcard(REDIS_KEY)
           │    │  │     └ 'proxy:baidu'
           │    │  └ <function Redis.zcard at 0x0000021BE557DD38>
           │    └ Redis<ConnectionPool<Connection<host=localhost,port=6379,db=0>>>
           └ <proxypool.components.redisclient.RedisClient object at 0x0000021BE566E708>

  File "D:\Apps\Python\miniconda3\envs\py37\lib\site-packages\redis\client.py", line 2692, in zcard
    return self.execute_command('ZCARD', name)
           │    │                        └ 'proxy:baidu'
           │    └ <function Redis.execute_command at 0x0000021BE5576D38>
           └ Redis<ConnectionPool<Connection<host=localhost,port=6379,db=0>>>

  File "D:\Apps\Python\miniconda3\envs\py37\lib\site-packages\redis\client.py", line 898, in execute_command
    conn = self.connection or pool.get_connection(command_name, **options)
           │    │             │    │              │               └ {}
           │    │             │    │              └ 'ZCARD'
           │    │             │    └ <function ConnectionPool.get_connection at 0x0000021BE555FD38>
           │    │             └ ConnectionPool<Connection<host=localhost,port=6379,db=0>>
           │    └ None
           └ Redis<ConnectionPool<Connection<host=localhost,port=6379,db=0>>>

  File "D:\Apps\Python\miniconda3\envs\py37\lib\site-packages\redis\connection.py", line 1192, in get_connection
    connection.connect()
    │          └ <function Connection.connect at 0x0000021BE5558F78>
    └ Connection<host=localhost,port=6379,db=0>

  File "D:\Apps\Python\miniconda3\envs\py37\lib\site-packages\redis\connection.py", line 563, in connect
    raise ConnectionError(self._error_message(e))
          │               │    └ <function Connection._error_message at 0x0000021BE555F0D8>
          │               └ Connection<host=localhost,port=6379,db=0>
          └ <class 'redis.exceptions.ConnectionError'>

redis.exceptions.ConnectionError: Error 10061 connecting to localhost:6379. 由于目标计算机积极拒绝，无法连接。.
2022-01-16 11:07:47 - ERROR - getter.py - 35 - An error has been caught in function '<module>', process 'MainProcess' (620), thread 'MainThread' (13020):
Traceback (most recent call last):

  File "D:\Apps\Python\miniconda3\envs\py37\lib\site-packages\redis\connection.py", line 559, in connect
    sock = self._connect()
           │    └ <function Connection._connect at 0x0000021BE555F048>
           └ Connection<host=localhost,port=6379,db=0>

  File "D:\Apps\Python\miniconda3\envs\py37\lib\site-packages\redis\connection.py", line 615, in _connect
    raise err
          └ ConnectionRefusedError(10061, '由于目标计算机积极拒绝，无法连接。', None, 10061, None)

  File "D:\Apps\Python\miniconda3\envs\py37\lib\site-packages\redis\connection.py", line 603, in _connect
    sock.connect(socket_address)
    │    │       └ ('127.0.0.1', 6379)
    │    └ <method 'connect' of '_socket.socket' objects>
    └ <socket.socket [closed] fd=-1, family=AddressFamily.AF_INET, type=SocketKind.SOCK_STREAM, proto=0>

ConnectionRefusedError: [WinError 10061] 由于目标计算机积极拒绝，无法连接。


During handling of the above exception, another exception occurred:


Traceback (most recent call last):

> File "D:/WorkSpace/pycharm-workspace/ProxyPool/proxypool/components/getter.py", line 35, in <module>
    getter.run()
    │      └ <function Getter.run at 0x0000021BE56783A8>
    └ <__main__.Getter object at 0x0000021BE2D2A348>

  File "D:/WorkSpace/pycharm-workspace/ProxyPool/proxypool/components/getter.py", line 25, in run
    if self.is_full():
       │    └ <function Getter.is_full at 0x0000021BE5678288>
       └ <__main__.Getter object at 0x0000021BE2D2A348>

  File "D:/WorkSpace/pycharm-workspace/ProxyPool/proxypool/components/getter.py", line 21, in is_full
    return self.redis.count() >= PROXY_NUMBER_MAX
           │    │     │          └ 50000
           │    │     └ <function RedisClient.count at 0x0000021BE5670DC8>
           │    └ <proxypool.components.redisclient.RedisClient object at 0x0000021BE566E708>
           └ <__main__.Getter object at 0x0000021BE2D2A348>

  File "D:\WorkSpace\pycharm-workspace\ProxyPool\proxypool\components\redisclient.py", line 48, in count
    return self.db.zcard(REDIS_KEY)
           │    │  │     └ 'proxy:baidu'
           │    │  └ <function Redis.zcard at 0x0000021BE557DD38>
           │    └ Redis<ConnectionPool<Connection<host=localhost,port=6379,db=0>>>
           └ <proxypool.components.redisclient.RedisClient object at 0x0000021BE566E708>

  File "D:\Apps\Python\miniconda3\envs\py37\lib\site-packages\redis\client.py", line 2692, in zcard
    return self.execute_command('ZCARD', name)
           │    │                        └ 'proxy:baidu'
           │    └ <function Redis.execute_command at 0x0000021BE5576D38>
           └ Redis<ConnectionPool<Connection<host=localhost,port=6379,db=0>>>

  File "D:\Apps\Python\miniconda3\envs\py37\lib\site-packages\redis\client.py", line 898, in execute_command
    conn = self.connection or pool.get_connection(command_name, **options)
           │    │             │    │              │               └ {}
           │    │             │    │              └ 'ZCARD'
           │    │             │    └ <function ConnectionPool.get_connection at 0x0000021BE555FD38>
           │    │             └ ConnectionPool<Connection<host=localhost,port=6379,db=0>>
           │    └ None
           └ Redis<ConnectionPool<Connection<host=localhost,port=6379,db=0>>>

  File "D:\Apps\Python\miniconda3\envs\py37\lib\site-packages\redis\connection.py", line 1192, in get_connection
    connection.connect()
    │          └ <function Connection.connect at 0x0000021BE5558F78>
    └ Connection<host=localhost,port=6379,db=0>

  File "D:\Apps\Python\miniconda3\envs\py37\lib\site-packages\redis\connection.py", line 563, in connect
    raise ConnectionError(self._error_message(e))
          │               │    └ <function Connection._error_message at 0x0000021BE555F0D8>
          │               └ Connection<host=localhost,port=6379,db=0>
          └ <class 'redis.exceptions.ConnectionError'>

redis.exceptions.ConnectionError: Error 10061 connecting to localhost:6379. 由于目标计算机积极拒绝，无法连接。.
